2019-07-14 02:13:00.688 7609 INFO keyring.backend [-] Loading Windows (alt)
2019-07-14 02:13:00.702 7609 INFO keyring.backend [-] Loading pyfs
2019-07-14 02:13:00.704 7609 INFO keyring.backend [-] Loading multi
2019-07-14 02:13:00.704 7609 INFO keyring.backend [-] Loading Google
2019-07-14 02:13:00.707 7609 INFO keyring.backend [-] Loading Gnome
2019-07-14 02:13:00.712 7609 INFO keyring.backend [-] Loading keyczar
2019-07-14 02:13:00.713 7609 INFO keyring.backend [-] Loading file
2019-07-14 02:13:02.665 7605 INFO keyring.backend [-] Loading Windows (alt)
2019-07-14 02:13:02.680 7605 INFO keyring.backend [-] Loading pyfs
2019-07-14 02:13:02.705 7605 INFO keyring.backend [-] Loading multi
2019-07-14 02:13:02.706 7605 INFO keyring.backend [-] Loading Google
2019-07-14 02:13:02.709 7605 INFO keyring.backend [-] Loading Gnome
2019-07-14 02:13:02.715 7605 INFO keyring.backend [-] Loading keyczar
2019-07-14 02:13:02.715 7605 INFO keyring.backend [-] Loading file
2019-07-14 02:13:02.825 7605 INFO keystone.common.wsgi [req-eff733aa-7742-4b1a-9e26-372e277b0ae8 - - - - -] POST http://controller:5000/v3/auth/tokens
2019-07-14 02:13:02.841 7605 WARNING oslo_db.sqlalchemy.engines [req-eff733aa-7742-4b1a-9e26-372e277b0ae8 - - - - -] SQL connection failed. 10 attempts left.: DBConnectionError: (pymysql.err.OperationalError) (2003, "Can't connect to MySQL server on 'controller' ([Errno 111] Connection refused)") (Background on this error at: http://sqlalche.me/e/e3q8)
2019-07-14 02:13:12.854 7605 WARNING oslo_db.sqlalchemy.engines [req-eff733aa-7742-4b1a-9e26-372e277b0ae8 - - - - -] SQL connection failed. 9 attempts left.: DBConnectionError: (pymysql.err.OperationalError) (2003, "Can't connect to MySQL server on 'controller' ([Errno 111] Connection refused)") (Background on this error at: http://sqlalche.me/e/e3q8)
2019-07-14 02:13:22.866 7605 WARNING oslo_db.sqlalchemy.engines [req-eff733aa-7742-4b1a-9e26-372e277b0ae8 - - - - -] SQL connection failed. 8 attempts left.: DBConnectionError: (pymysql.err.OperationalError) (2003, "Can't connect to MySQL server on 'controller' ([Errno 111] Connection refused)") (Background on this error at: http://sqlalche.me/e/e3q8)
2019-07-14 02:13:32.878 7605 WARNING oslo_db.sqlalchemy.engines [req-eff733aa-7742-4b1a-9e26-372e277b0ae8 - - - - -] SQL connection failed. 7 attempts left.: DBConnectionError: (pymysql.err.OperationalError) (2003, "Can't connect to MySQL server on 'controller' ([Errno 111] Connection refused)") (Background on this error at: http://sqlalche.me/e/e3q8)
2019-07-14 02:13:42.889 7605 WARNING oslo_db.sqlalchemy.engines [req-eff733aa-7742-4b1a-9e26-372e277b0ae8 - - - - -] SQL connection failed. 6 attempts left.: DBConnectionError: (pymysql.err.OperationalError) (2003, "Can't connect to MySQL server on 'controller' ([Errno 111] Connection refused)") (Background on this error at: http://sqlalche.me/e/e3q8)
2019-07-14 02:13:52.901 7605 WARNING oslo_db.sqlalchemy.engines [req-eff733aa-7742-4b1a-9e26-372e277b0ae8 - - - - -] SQL connection failed. 5 attempts left.: DBConnectionError: (pymysql.err.OperationalError) (2003, "Can't connect to MySQL server on 'controller' ([Errno 111] Connection refused)") (Background on this error at: http://sqlalche.me/e/e3q8)
2019-07-14 02:14:02.913 7605 WARNING oslo_db.sqlalchemy.engines [req-eff733aa-7742-4b1a-9e26-372e277b0ae8 - - - - -] SQL connection failed. 4 attempts left.: DBConnectionError: (pymysql.err.OperationalError) (2003, "Can't connect to MySQL server on 'controller' ([Errno 111] Connection refused)") (Background on this error at: http://sqlalche.me/e/e3q8)
2019-07-14 02:14:12.925 7605 WARNING oslo_db.sqlalchemy.engines [req-eff733aa-7742-4b1a-9e26-372e277b0ae8 - - - - -] SQL connection failed. 3 attempts left.: DBConnectionError: (pymysql.err.OperationalError) (2003, "Can't connect to MySQL server on 'controller' ([Errno 111] Connection refused)") (Background on this error at: http://sqlalche.me/e/e3q8)
2019-07-14 02:14:22.937 7605 WARNING oslo_db.sqlalchemy.engines [req-eff733aa-7742-4b1a-9e26-372e277b0ae8 - - - - -] SQL connection failed. 2 attempts left.: DBConnectionError: (pymysql.err.OperationalError) (2003, "Can't connect to MySQL server on 'controller' ([Errno 111] Connection refused)") (Background on this error at: http://sqlalche.me/e/e3q8)
2019-07-14 02:14:32.949 7605 WARNING oslo_db.sqlalchemy.engines [req-eff733aa-7742-4b1a-9e26-372e277b0ae8 - - - - -] SQL connection failed. 1 attempts left.: DBConnectionError: (pymysql.err.OperationalError) (2003, "Can't connect to MySQL server on 'controller' ([Errno 111] Connection refused)") (Background on this error at: http://sqlalche.me/e/e3q8)
2019-07-14 02:14:42.961 7605 ERROR keystone.common.wsgi [req-eff733aa-7742-4b1a-9e26-372e277b0ae8 - - - - -] (pymysql.err.OperationalError) (2003, "Can't connect to MySQL server on 'controller' ([Errno 111] Connection refused)") (Background on this error at: http://sqlalche.me/e/e3q8): DBConnectionError: (pymysql.err.OperationalError) (2003, "Can't connect to MySQL server on 'controller' ([Errno 111] Connection refused)") (Background on this error at: http://sqlalche.me/e/e3q8)
2019-07-14 02:14:42.961 7605 ERROR keystone.common.wsgi Traceback (most recent call last):
2019-07-14 02:14:42.961 7605 ERROR keystone.common.wsgi   File "/usr/lib/python2.7/dist-packages/keystone/common/wsgi.py", line 148, in __call__
2019-07-14 02:14:42.961 7605 ERROR keystone.common.wsgi     result = method(req, **params)
2019-07-14 02:14:42.961 7605 ERROR keystone.common.wsgi   File "/usr/lib/python2.7/dist-packages/keystone/auth/controllers.py", line 64, in authenticate_for_token
2019-07-14 02:14:42.961 7605 ERROR keystone.common.wsgi     auth_info = core.AuthInfo.create(auth=auth)
2019-07-14 02:14:42.961 7605 ERROR keystone.common.wsgi   File "/usr/lib/python2.7/dist-packages/keystone/auth/core.py", line 128, in create
2019-07-14 02:14:42.961 7605 ERROR keystone.common.wsgi     auth_info._validate_and_normalize_auth_data(scope_only)
2019-07-14 02:14:42.961 7605 ERROR keystone.common.wsgi   File "/usr/lib/python2.7/dist-packages/keystone/auth/core.py", line 336, in _validate_and_normalize_auth_data
2019-07-14 02:14:42.961 7605 ERROR keystone.common.wsgi     self._validate_and_normalize_scope_data()
2019-07-14 02:14:42.961 7605 ERROR keystone.common.wsgi   File "/usr/lib/python2.7/dist-packages/keystone/auth/core.py", line 286, in _validate_and_normalize_scope_data
2019-07-14 02:14:42.961 7605 ERROR keystone.common.wsgi     project_ref = self._lookup_project(self.auth['scope']['project'])
2019-07-14 02:14:42.961 7605 ERROR keystone.common.wsgi   File "/usr/lib/python2.7/dist-packages/keystone/auth/core.py", line 196, in _lookup_project
2019-07-14 02:14:42.961 7605 ERROR keystone.common.wsgi     domain_ref = self._lookup_domain(project_info['domain'])
2019-07-14 02:14:42.961 7605 ERROR keystone.common.wsgi   File "/usr/lib/python2.7/dist-packages/keystone/auth/core.py", line 174, in _lookup_domain
2019-07-14 02:14:42.961 7605 ERROR keystone.common.wsgi     domain_name)
2019-07-14 02:14:42.961 7605 ERROR keystone.common.wsgi   File "/usr/lib/python2.7/dist-packages/keystone/common/manager.py", line 116, in wrapped
2019-07-14 02:14:42.961 7605 ERROR keystone.common.wsgi     __ret_val = __f(*args, **kwargs)
2019-07-14 02:14:42.961 7605 ERROR keystone.common.wsgi   File "/usr/lib/python2.7/dist-packages/dogpile/cache/region.py", line 1220, in decorate
2019-07-14 02:14:42.961 7605 ERROR keystone.common.wsgi     should_cache_fn)
2019-07-14 02:14:42.961 7605 ERROR keystone.common.wsgi   File "/usr/lib/python2.7/dist-packages/dogpile/cache/region.py", line 825, in get_or_create
2019-07-14 02:14:42.961 7605 ERROR keystone.common.wsgi     async_creator) as value:
2019-07-14 02:14:42.961 7605 ERROR keystone.common.wsgi   File "/usr/lib/python2.7/dist-packages/dogpile/lock.py", line 154, in __enter__
2019-07-14 02:14:42.961 7605 ERROR keystone.common.wsgi     return self._enter()
2019-07-14 02:14:42.961 7605 ERROR keystone.common.wsgi   File "/usr/lib/python2.7/dist-packages/dogpile/lock.py", line 94, in _enter
2019-07-14 02:14:42.961 7605 ERROR keystone.common.wsgi     generated = self._enter_create(createdtime)
2019-07-14 02:14:42.961 7605 ERROR keystone.common.wsgi   File "/usr/lib/python2.7/dist-packages/dogpile/lock.py", line 145, in _enter_create
2019-07-14 02:14:42.961 7605 ERROR keystone.common.wsgi     created = self.creator()
2019-07-14 02:14:42.961 7605 ERROR keystone.common.wsgi   File "/usr/lib/python2.7/dist-packages/dogpile/cache/region.py", line 792, in gen_value
2019-07-14 02:14:42.961 7605 ERROR keystone.common.wsgi     created_value = creator()
2019-07-14 02:14:42.961 7605 ERROR keystone.common.wsgi   File "/usr/lib/python2.7/dist-packages/dogpile/cache/region.py", line 1216, in creator
2019-07-14 02:14:42.961 7605 ERROR keystone.common.wsgi     return fn(*arg, **kw)
2019-07-14 02:14:42.961 7605 ERROR keystone.common.wsgi   File "/usr/lib/python2.7/dist-packages/keystone/resource/core.py", line 716, in get_domain_by_name
2019-07-14 02:14:42.961 7605 ERROR keystone.common.wsgi     domain_id=None)
2019-07-14 02:14:42.961 7605 ERROR keystone.common.wsgi   File "/usr/lib/python2.7/dist-packages/keystone/resource/backends/sql.py", line 55, in get_project_by_name
2019-07-14 02:14:42.961 7605 ERROR keystone.common.wsgi     with sql.session_for_read() as session:
2019-07-14 02:14:42.961 7605 ERROR keystone.common.wsgi   File "/usr/lib/python2.7/contextlib.py", line 17, in __enter__
2019-07-14 02:14:42.961 7605 ERROR keystone.common.wsgi     return self.gen.next()
2019-07-14 02:14:42.961 7605 ERROR keystone.common.wsgi   File "/usr/lib/python2.7/dist-packages/oslo_db/sqlalchemy/enginefacade.py", line 1042, in _transaction_scope
2019-07-14 02:14:42.961 7605 ERROR keystone.common.wsgi     context=context) as resource:
2019-07-14 02:14:42.961 7605 ERROR keystone.common.wsgi   File "/usr/lib/python2.7/contextlib.py", line 17, in __enter__
2019-07-14 02:14:42.961 7605 ERROR keystone.common.wsgi     return self.gen.next()
2019-07-14 02:14:42.961 7605 ERROR keystone.common.wsgi   File "/usr/lib/python2.7/dist-packages/oslo_db/sqlalchemy/enginefacade.py", line 645, in _session
2019-07-14 02:14:42.961 7605 ERROR keystone.common.wsgi     bind=self.connection, mode=self.mode)
2019-07-14 02:14:42.961 7605 ERROR keystone.common.wsgi   File "/usr/lib/python2.7/dist-packages/oslo_db/sqlalchemy/enginefacade.py", line 409, in _create_session
2019-07-14 02:14:42.961 7605 ERROR keystone.common.wsgi     self._start()
2019-07-14 02:14:42.961 7605 ERROR keystone.common.wsgi   File "/usr/lib/python2.7/dist-packages/oslo_db/sqlalchemy/enginefacade.py", line 496, in _start
2019-07-14 02:14:42.961 7605 ERROR keystone.common.wsgi     engine_args, maker_args)
2019-07-14 02:14:42.961 7605 ERROR keystone.common.wsgi   File "/usr/lib/python2.7/dist-packages/oslo_db/sqlalchemy/enginefacade.py", line 520, in _setup_for_connection
2019-07-14 02:14:42.961 7605 ERROR keystone.common.wsgi     sql_connection=sql_connection, **engine_kwargs)
2019-07-14 02:14:42.961 7605 ERROR keystone.common.wsgi   File "/usr/lib/python2.7/dist-packages/debtcollector/renames.py", line 43, in decorator
2019-07-14 02:14:42.961 7605 ERROR keystone.common.wsgi     return wrapped(*args, **kwargs)
2019-07-14 02:14:42.961 7605 ERROR keystone.common.wsgi   File "/usr/lib/python2.7/dist-packages/oslo_db/sqlalchemy/engines.py", line 202, in create_engine
2019-07-14 02:14:42.961 7605 ERROR keystone.common.wsgi     test_conn = _test_connection(engine, max_retries, retry_interval)
2019-07-14 02:14:42.961 7605 ERROR keystone.common.wsgi   File "/usr/lib/python2.7/dist-packages/oslo_db/sqlalchemy/engines.py", line 388, in _test_connection
2019-07-14 02:14:42.961 7605 ERROR keystone.common.wsgi     six.reraise(type(de_ref), de_ref)
2019-07-14 02:14:42.961 7605 ERROR keystone.common.wsgi   File "<string>", line 3, in reraise
2019-07-14 02:14:42.961 7605 ERROR keystone.common.wsgi DBConnectionError: (pymysql.err.OperationalError) (2003, "Can't connect to MySQL server on 'controller' ([Errno 111] Connection refused)") (Background on this error at: http://sqlalche.me/e/e3q8)
2019-07-14 02:14:42.961 7605 ERROR keystone.common.wsgi 
2019-07-14 02:15:33.977 7605 INFO keystone.common.wsgi [req-4b497bd7-5140-461a-9b9a-72fc3722b379 - - - - -] POST http://controller:5000/v3/auth/tokens
2019-07-14 02:15:33.982 7605 WARNING oslo_db.sqlalchemy.engines [req-4b497bd7-5140-461a-9b9a-72fc3722b379 - - - - -] SQL connection failed. 10 attempts left.: DBConnectionError: (pymysql.err.OperationalError) (2003, "Can't connect to MySQL server on 'controller' ([Errno 111] Connection refused)") (Background on this error at: http://sqlalche.me/e/e3q8)
2019-07-14 02:15:43.993 7605 WARNING oslo_db.sqlalchemy.engines [req-4b497bd7-5140-461a-9b9a-72fc3722b379 - - - - -] SQL connection failed. 9 attempts left.: DBConnectionError: (pymysql.err.OperationalError) (2003, "Can't connect to MySQL server on 'controller' ([Errno 111] Connection refused)") (Background on this error at: http://sqlalche.me/e/e3q8)
2019-07-14 02:15:54.005 7605 WARNING oslo_db.sqlalchemy.engines [req-4b497bd7-5140-461a-9b9a-72fc3722b379 - - - - -] SQL connection failed. 8 attempts left.: DBConnectionError: (pymysql.err.OperationalError) (2003, "Can't connect to MySQL server on 'controller' ([Errno 111] Connection refused)") (Background on this error at: http://sqlalche.me/e/e3q8)
2019-07-14 02:16:04.016 7605 WARNING oslo_db.sqlalchemy.engines [req-4b497bd7-5140-461a-9b9a-72fc3722b379 - - - - -] SQL connection failed. 7 attempts left.: DBConnectionError: (pymysql.err.OperationalError) (2003, "Can't connect to MySQL server on 'controller' ([Errno 111] Connection refused)") (Background on this error at: http://sqlalche.me/e/e3q8)
2019-07-14 02:16:14.028 7605 WARNING oslo_db.sqlalchemy.engines [req-4b497bd7-5140-461a-9b9a-72fc3722b379 - - - - -] SQL connection failed. 6 attempts left.: DBConnectionError: (pymysql.err.OperationalError) (2003, "Can't connect to MySQL server on 'controller' ([Errno 111] Connection refused)") (Background on this error at: http://sqlalche.me/e/e3q8)
2019-07-14 02:16:24.033 7605 WARNING oslo_db.sqlalchemy.engines [req-4b497bd7-5140-461a-9b9a-72fc3722b379 - - - - -] SQL connection failed. 5 attempts left.: DBConnectionError: (pymysql.err.OperationalError) (2003, "Can't connect to MySQL server on 'controller' ([Errno 111] Connection refused)") (Background on this error at: http://sqlalche.me/e/e3q8)
2019-07-14 02:16:34.045 7605 WARNING oslo_db.sqlalchemy.engines [req-4b497bd7-5140-461a-9b9a-72fc3722b379 - - - - -] SQL connection failed. 4 attempts left.: DBConnectionError: (pymysql.err.OperationalError) (2003, "Can't connect to MySQL server on 'controller' ([Errno 111] Connection refused)") (Background on this error at: http://sqlalche.me/e/e3q8)
2019-07-14 02:16:44.056 7605 WARNING oslo_db.sqlalchemy.engines [req-4b497bd7-5140-461a-9b9a-72fc3722b379 - - - - -] SQL connection failed. 3 attempts left.: DBConnectionError: (pymysql.err.OperationalError) (2003, "Can't connect to MySQL server on 'controller' ([Errno 111] Connection refused)") (Background on this error at: http://sqlalche.me/e/e3q8)
2019-07-14 02:16:54.068 7605 WARNING oslo_db.sqlalchemy.engines [req-4b497bd7-5140-461a-9b9a-72fc3722b379 - - - - -] SQL connection failed. 2 attempts left.: DBConnectionError: (pymysql.err.OperationalError) (2003, "Can't connect to MySQL server on 'controller' ([Errno 111] Connection refused)") (Background on this error at: http://sqlalche.me/e/e3q8)
2019-07-14 02:17:04.080 7605 WARNING oslo_db.sqlalchemy.engines [req-4b497bd7-5140-461a-9b9a-72fc3722b379 - - - - -] SQL connection failed. 1 attempts left.: DBConnectionError: (pymysql.err.OperationalError) (2003, "Can't connect to MySQL server on 'controller' ([Errno 111] Connection refused)") (Background on this error at: http://sqlalche.me/e/e3q8)
2019-07-14 02:17:14.085 7605 ERROR keystone.common.wsgi [req-4b497bd7-5140-461a-9b9a-72fc3722b379 - - - - -] (pymysql.err.OperationalError) (2003, "Can't connect to MySQL server on 'controller' ([Errno 111] Connection refused)") (Background on this error at: http://sqlalche.me/e/e3q8): DBConnectionError: (pymysql.err.OperationalError) (2003, "Can't connect to MySQL server on 'controller' ([Errno 111] Connection refused)") (Background on this error at: http://sqlalche.me/e/e3q8)
2019-07-14 02:17:14.085 7605 ERROR keystone.common.wsgi Traceback (most recent call last):
2019-07-14 02:17:14.085 7605 ERROR keystone.common.wsgi   File "/usr/lib/python2.7/dist-packages/keystone/common/wsgi.py", line 148, in __call__
2019-07-14 02:17:14.085 7605 ERROR keystone.common.wsgi     result = method(req, **params)
2019-07-14 02:17:14.085 7605 ERROR keystone.common.wsgi   File "/usr/lib/python2.7/dist-packages/keystone/auth/controllers.py", line 64, in authenticate_for_token
2019-07-14 02:17:14.085 7605 ERROR keystone.common.wsgi     auth_info = core.AuthInfo.create(auth=auth)
2019-07-14 02:17:14.085 7605 ERROR keystone.common.wsgi   File "/usr/lib/python2.7/dist-packages/keystone/auth/core.py", line 128, in create
2019-07-14 02:17:14.085 7605 ERROR keystone.common.wsgi     auth_info._validate_and_normalize_auth_data(scope_only)
2019-07-14 02:17:14.085 7605 ERROR keystone.common.wsgi   File "/usr/lib/python2.7/dist-packages/keystone/auth/core.py", line 336, in _validate_and_normalize_auth_data
2019-07-14 02:17:14.085 7605 ERROR keystone.common.wsgi     self._validate_and_normalize_scope_data()
2019-07-14 02:17:14.085 7605 ERROR keystone.common.wsgi   File "/usr/lib/python2.7/dist-packages/keystone/auth/core.py", line 286, in _validate_and_normalize_scope_data
2019-07-14 02:17:14.085 7605 ERROR keystone.common.wsgi     project_ref = self._lookup_project(self.auth['scope']['project'])
2019-07-14 02:17:14.085 7605 ERROR keystone.common.wsgi   File "/usr/lib/python2.7/dist-packages/keystone/auth/core.py", line 196, in _lookup_project
2019-07-14 02:17:14.085 7605 ERROR keystone.common.wsgi     domain_ref = self._lookup_domain(project_info['domain'])
2019-07-14 02:17:14.085 7605 ERROR keystone.common.wsgi   File "/usr/lib/python2.7/dist-packages/keystone/auth/core.py", line 174, in _lookup_domain
2019-07-14 02:17:14.085 7605 ERROR keystone.common.wsgi     domain_name)
2019-07-14 02:17:14.085 7605 ERROR keystone.common.wsgi   File "/usr/lib/python2.7/dist-packages/keystone/common/manager.py", line 116, in wrapped
2019-07-14 02:17:14.085 7605 ERROR keystone.common.wsgi     __ret_val = __f(*args, **kwargs)
2019-07-14 02:17:14.085 7605 ERROR keystone.common.wsgi   File "/usr/lib/python2.7/dist-packages/dogpile/cache/region.py", line 1220, in decorate
2019-07-14 02:17:14.085 7605 ERROR keystone.common.wsgi     should_cache_fn)
2019-07-14 02:17:14.085 7605 ERROR keystone.common.wsgi   File "/usr/lib/python2.7/dist-packages/dogpile/cache/region.py", line 825, in get_or_create
2019-07-14 02:17:14.085 7605 ERROR keystone.common.wsgi     async_creator) as value:
2019-07-14 02:17:14.085 7605 ERROR keystone.common.wsgi   File "/usr/lib/python2.7/dist-packages/dogpile/lock.py", line 154, in __enter__
2019-07-14 02:17:14.085 7605 ERROR keystone.common.wsgi     return self._enter()
2019-07-14 02:17:14.085 7605 ERROR keystone.common.wsgi   File "/usr/lib/python2.7/dist-packages/dogpile/lock.py", line 94, in _enter
2019-07-14 02:17:14.085 7605 ERROR keystone.common.wsgi     generated = self._enter_create(createdtime)
2019-07-14 02:17:14.085 7605 ERROR keystone.common.wsgi   File "/usr/lib/python2.7/dist-packages/dogpile/lock.py", line 145, in _enter_create
2019-07-14 02:17:14.085 7605 ERROR keystone.common.wsgi     created = self.creator()
2019-07-14 02:17:14.085 7605 ERROR keystone.common.wsgi   File "/usr/lib/python2.7/dist-packages/dogpile/cache/region.py", line 792, in gen_value
2019-07-14 02:17:14.085 7605 ERROR keystone.common.wsgi     created_value = creator()
2019-07-14 02:17:14.085 7605 ERROR keystone.common.wsgi   File "/usr/lib/python2.7/dist-packages/dogpile/cache/region.py", line 1216, in creator
2019-07-14 02:17:14.085 7605 ERROR keystone.common.wsgi     return fn(*arg, **kw)
2019-07-14 02:17:14.085 7605 ERROR keystone.common.wsgi   File "/usr/lib/python2.7/dist-packages/keystone/resource/core.py", line 716, in get_domain_by_name
2019-07-14 02:17:14.085 7605 ERROR keystone.common.wsgi     domain_id=None)
2019-07-14 02:17:14.085 7605 ERROR keystone.common.wsgi   File "/usr/lib/python2.7/dist-packages/keystone/resource/backends/sql.py", line 55, in get_project_by_name
2019-07-14 02:17:14.085 7605 ERROR keystone.common.wsgi     with sql.session_for_read() as session:
2019-07-14 02:17:14.085 7605 ERROR keystone.common.wsgi   File "/usr/lib/python2.7/contextlib.py", line 17, in __enter__
2019-07-14 02:17:14.085 7605 ERROR keystone.common.wsgi     return self.gen.next()
2019-07-14 02:17:14.085 7605 ERROR keystone.common.wsgi   File "/usr/lib/python2.7/dist-packages/oslo_db/sqlalchemy/enginefacade.py", line 1042, in _transaction_scope
2019-07-14 02:17:14.085 7605 ERROR keystone.common.wsgi     context=context) as resource:
2019-07-14 02:17:14.085 7605 ERROR keystone.common.wsgi   File "/usr/lib/python2.7/contextlib.py", line 17, in __enter__
2019-07-14 02:17:14.085 7605 ERROR keystone.common.wsgi     return self.gen.next()
2019-07-14 02:17:14.085 7605 ERROR keystone.common.wsgi   File "/usr/lib/python2.7/dist-packages/oslo_db/sqlalchemy/enginefacade.py", line 645, in _session
2019-07-14 02:17:14.085 7605 ERROR keystone.common.wsgi     bind=self.connection, mode=self.mode)
2019-07-14 02:17:14.085 7605 ERROR keystone.common.wsgi   File "/usr/lib/python2.7/dist-packages/oslo_db/sqlalchemy/enginefacade.py", line 409, in _create_session
2019-07-14 02:17:14.085 7605 ERROR keystone.common.wsgi     self._start()
2019-07-14 02:17:14.085 7605 ERROR keystone.common.wsgi   File "/usr/lib/python2.7/dist-packages/oslo_db/sqlalchemy/enginefacade.py", line 496, in _start
2019-07-14 02:17:14.085 7605 ERROR keystone.common.wsgi     engine_args, maker_args)
2019-07-14 02:17:14.085 7605 ERROR keystone.common.wsgi   File "/usr/lib/python2.7/dist-packages/oslo_db/sqlalchemy/enginefacade.py", line 520, in _setup_for_connection
2019-07-14 02:17:14.085 7605 ERROR keystone.common.wsgi     sql_connection=sql_connection, **engine_kwargs)
2019-07-14 02:17:14.085 7605 ERROR keystone.common.wsgi   File "/usr/lib/python2.7/dist-packages/debtcollector/renames.py", line 43, in decorator
2019-07-14 02:17:14.085 7605 ERROR keystone.common.wsgi     return wrapped(*args, **kwargs)
2019-07-14 02:17:14.085 7605 ERROR keystone.common.wsgi   File "/usr/lib/python2.7/dist-packages/oslo_db/sqlalchemy/engines.py", line 202, in create_engine
2019-07-14 02:17:14.085 7605 ERROR keystone.common.wsgi     test_conn = _test_connection(engine, max_retries, retry_interval)
2019-07-14 02:17:14.085 7605 ERROR keystone.common.wsgi   File "/usr/lib/python2.7/dist-packages/oslo_db/sqlalchemy/engines.py", line 388, in _test_connection
2019-07-14 02:17:14.085 7605 ERROR keystone.common.wsgi     six.reraise(type(de_ref), de_ref)
2019-07-14 02:17:14.085 7605 ERROR keystone.common.wsgi   File "<string>", line 3, in reraise
2019-07-14 02:17:14.085 7605 ERROR keystone.common.wsgi DBConnectionError: (pymysql.err.OperationalError) (2003, "Can't connect to MySQL server on 'controller' ([Errno 111] Connection refused)") (Background on this error at: http://sqlalche.me/e/e3q8)
2019-07-14 02:17:14.085 7605 ERROR keystone.common.wsgi 
2019-07-14 02:59:12.392 9180 INFO keyring.backend [-] Loading Windows (alt)
2019-07-14 02:59:12.406 9180 INFO keyring.backend [-] Loading pyfs
2019-07-14 02:59:12.407 9180 INFO keyring.backend [-] Loading multi
2019-07-14 02:59:12.407 9180 INFO keyring.backend [-] Loading Google
2019-07-14 02:59:12.410 9180 INFO keyring.backend [-] Loading Gnome
2019-07-14 02:59:12.415 9180 INFO keyring.backend [-] Loading keyczar
2019-07-14 02:59:12.416 9180 INFO keyring.backend [-] Loading file
2019-07-14 02:59:14.359 9182 INFO keyring.backend [-] Loading Windows (alt)
2019-07-14 02:59:14.372 9182 INFO keyring.backend [-] Loading pyfs
2019-07-14 02:59:14.374 9182 INFO keyring.backend [-] Loading multi
2019-07-14 02:59:14.374 9182 INFO keyring.backend [-] Loading Google
2019-07-14 02:59:14.376 9182 INFO keyring.backend [-] Loading Gnome
2019-07-14 02:59:14.382 9182 INFO keyring.backend [-] Loading keyczar
2019-07-14 02:59:14.383 9182 INFO keyring.backend [-] Loading file
2019-07-14 02:59:14.490 9182 INFO keystone.common.wsgi [req-9b1aaf74-4830-41c8-88a6-1084d5715946 - - - - -] POST http://controller:5000/v3/auth/tokens
2019-07-14 02:59:14.505 9182 WARNING oslo_db.sqlalchemy.engines [req-9b1aaf74-4830-41c8-88a6-1084d5715946 - - - - -] SQL connection failed. 10 attempts left.: DBConnectionError: (pymysql.err.OperationalError) (2003, "Can't connect to MySQL server on 'controller' ([Errno 111] Connection refused)") (Background on this error at: http://sqlalche.me/e/e3q8)
2019-07-14 02:59:24.518 9182 WARNING oslo_db.sqlalchemy.engines [req-9b1aaf74-4830-41c8-88a6-1084d5715946 - - - - -] SQL connection failed. 9 attempts left.: DBConnectionError: (pymysql.err.OperationalError) (2003, "Can't connect to MySQL server on 'controller' ([Errno 111] Connection refused)") (Background on this error at: http://sqlalche.me/e/e3q8)
2019-07-14 02:59:34.530 9182 WARNING oslo_db.sqlalchemy.engines [req-9b1aaf74-4830-41c8-88a6-1084d5715946 - - - - -] SQL connection failed. 8 attempts left.: DBConnectionError: (pymysql.err.OperationalError) (2003, "Can't connect to MySQL server on 'controller' ([Errno 111] Connection refused)") (Background on this error at: http://sqlalche.me/e/e3q8)
2019-07-14 02:59:44.541 9182 WARNING oslo_db.sqlalchemy.engines [req-9b1aaf74-4830-41c8-88a6-1084d5715946 - - - - -] SQL connection failed. 7 attempts left.: DBConnectionError: (pymysql.err.OperationalError) (2003, "Can't connect to MySQL server on 'controller' ([Errno 111] Connection refused)") (Background on this error at: http://sqlalche.me/e/e3q8)
2019-07-14 02:59:54.553 9182 WARNING oslo_db.sqlalchemy.engines [req-9b1aaf74-4830-41c8-88a6-1084d5715946 - - - - -] SQL connection failed. 6 attempts left.: DBConnectionError: (pymysql.err.OperationalError) (2003, "Can't connect to MySQL server on 'controller' ([Errno 111] Connection refused)") (Background on this error at: http://sqlalche.me/e/e3q8)
2019-07-14 03:00:04.565 9182 WARNING oslo_db.sqlalchemy.engines [req-9b1aaf74-4830-41c8-88a6-1084d5715946 - - - - -] SQL connection failed. 5 attempts left.: DBConnectionError: (pymysql.err.OperationalError) (2003, "Can't connect to MySQL server on 'controller' ([Errno 111] Connection refused)") (Background on this error at: http://sqlalche.me/e/e3q8)
2019-07-14 03:00:14.577 9182 WARNING oslo_db.sqlalchemy.engines [req-9b1aaf74-4830-41c8-88a6-1084d5715946 - - - - -] SQL connection failed. 4 attempts left.: DBConnectionError: (pymysql.err.OperationalError) (2003, "Can't connect to MySQL server on 'controller' ([Errno 111] Connection refused)") (Background on this error at: http://sqlalche.me/e/e3q8)
2019-07-14 03:00:24.589 9182 WARNING oslo_db.sqlalchemy.engines [req-9b1aaf74-4830-41c8-88a6-1084d5715946 - - - - -] SQL connection failed. 3 attempts left.: DBConnectionError: (pymysql.err.OperationalError) (2003, "Can't connect to MySQL server on 'controller' ([Errno 111] Connection refused)") (Background on this error at: http://sqlalche.me/e/e3q8)
2019-07-14 03:00:34.601 9182 WARNING oslo_db.sqlalchemy.engines [req-9b1aaf74-4830-41c8-88a6-1084d5715946 - - - - -] SQL connection failed. 2 attempts left.: DBConnectionError: (pymysql.err.OperationalError) (2003, "Can't connect to MySQL server on 'controller' ([Errno 111] Connection refused)") (Background on this error at: http://sqlalche.me/e/e3q8)
2019-07-14 03:00:44.612 9182 WARNING oslo_db.sqlalchemy.engines [req-9b1aaf74-4830-41c8-88a6-1084d5715946 - - - - -] SQL connection failed. 1 attempts left.: DBConnectionError: (pymysql.err.OperationalError) (2003, "Can't connect to MySQL server on 'controller' ([Errno 111] Connection refused)") (Background on this error at: http://sqlalche.me/e/e3q8)
2019-07-14 03:00:54.623 9182 ERROR keystone.common.wsgi [req-9b1aaf74-4830-41c8-88a6-1084d5715946 - - - - -] (pymysql.err.OperationalError) (2003, "Can't connect to MySQL server on 'controller' ([Errno 111] Connection refused)") (Background on this error at: http://sqlalche.me/e/e3q8): DBConnectionError: (pymysql.err.OperationalError) (2003, "Can't connect to MySQL server on 'controller' ([Errno 111] Connection refused)") (Background on this error at: http://sqlalche.me/e/e3q8)
2019-07-14 03:00:54.623 9182 ERROR keystone.common.wsgi Traceback (most recent call last):
2019-07-14 03:00:54.623 9182 ERROR keystone.common.wsgi   File "/usr/lib/python2.7/dist-packages/keystone/common/wsgi.py", line 148, in __call__
2019-07-14 03:00:54.623 9182 ERROR keystone.common.wsgi     result = method(req, **params)
2019-07-14 03:00:54.623 9182 ERROR keystone.common.wsgi   File "/usr/lib/python2.7/dist-packages/keystone/auth/controllers.py", line 64, in authenticate_for_token
2019-07-14 03:00:54.623 9182 ERROR keystone.common.wsgi     auth_info = core.AuthInfo.create(auth=auth)
2019-07-14 03:00:54.623 9182 ERROR keystone.common.wsgi   File "/usr/lib/python2.7/dist-packages/keystone/auth/core.py", line 128, in create
2019-07-14 03:00:54.623 9182 ERROR keystone.common.wsgi     auth_info._validate_and_normalize_auth_data(scope_only)
2019-07-14 03:00:54.623 9182 ERROR keystone.common.wsgi   File "/usr/lib/python2.7/dist-packages/keystone/auth/core.py", line 336, in _validate_and_normalize_auth_data
2019-07-14 03:00:54.623 9182 ERROR keystone.common.wsgi     self._validate_and_normalize_scope_data()
2019-07-14 03:00:54.623 9182 ERROR keystone.common.wsgi   File "/usr/lib/python2.7/dist-packages/keystone/auth/core.py", line 286, in _validate_and_normalize_scope_data
2019-07-14 03:00:54.623 9182 ERROR keystone.common.wsgi     project_ref = self._lookup_project(self.auth['scope']['project'])
2019-07-14 03:00:54.623 9182 ERROR keystone.common.wsgi   File "/usr/lib/python2.7/dist-packages/keystone/auth/core.py", line 196, in _lookup_project
2019-07-14 03:00:54.623 9182 ERROR keystone.common.wsgi     domain_ref = self._lookup_domain(project_info['domain'])
2019-07-14 03:00:54.623 9182 ERROR keystone.common.wsgi   File "/usr/lib/python2.7/dist-packages/keystone/auth/core.py", line 174, in _lookup_domain
2019-07-14 03:00:54.623 9182 ERROR keystone.common.wsgi     domain_name)
2019-07-14 03:00:54.623 9182 ERROR keystone.common.wsgi   File "/usr/lib/python2.7/dist-packages/keystone/common/manager.py", line 116, in wrapped
2019-07-14 03:00:54.623 9182 ERROR keystone.common.wsgi     __ret_val = __f(*args, **kwargs)
2019-07-14 03:00:54.623 9182 ERROR keystone.common.wsgi   File "/usr/lib/python2.7/dist-packages/dogpile/cache/region.py", line 1220, in decorate
2019-07-14 03:00:54.623 9182 ERROR keystone.common.wsgi     should_cache_fn)
2019-07-14 03:00:54.623 9182 ERROR keystone.common.wsgi   File "/usr/lib/python2.7/dist-packages/dogpile/cache/region.py", line 825, in get_or_create
2019-07-14 03:00:54.623 9182 ERROR keystone.common.wsgi     async_creator) as value:
2019-07-14 03:00:54.623 9182 ERROR keystone.common.wsgi   File "/usr/lib/python2.7/dist-packages/dogpile/lock.py", line 154, in __enter__
2019-07-14 03:00:54.623 9182 ERROR keystone.common.wsgi     return self._enter()
2019-07-14 03:00:54.623 9182 ERROR keystone.common.wsgi   File "/usr/lib/python2.7/dist-packages/dogpile/lock.py", line 94, in _enter
2019-07-14 03:00:54.623 9182 ERROR keystone.common.wsgi     generated = self._enter_create(createdtime)
2019-07-14 03:00:54.623 9182 ERROR keystone.common.wsgi   File "/usr/lib/python2.7/dist-packages/dogpile/lock.py", line 145, in _enter_create
2019-07-14 03:00:54.623 9182 ERROR keystone.common.wsgi     created = self.creator()
2019-07-14 03:00:54.623 9182 ERROR keystone.common.wsgi   File "/usr/lib/python2.7/dist-packages/dogpile/cache/region.py", line 792, in gen_value
2019-07-14 03:00:54.623 9182 ERROR keystone.common.wsgi     created_value = creator()
2019-07-14 03:00:54.623 9182 ERROR keystone.common.wsgi   File "/usr/lib/python2.7/dist-packages/dogpile/cache/region.py", line 1216, in creator
2019-07-14 03:00:54.623 9182 ERROR keystone.common.wsgi     return fn(*arg, **kw)
2019-07-14 03:00:54.623 9182 ERROR keystone.common.wsgi   File "/usr/lib/python2.7/dist-packages/keystone/resource/core.py", line 716, in get_domain_by_name
2019-07-14 03:00:54.623 9182 ERROR keystone.common.wsgi     domain_id=None)
2019-07-14 03:00:54.623 9182 ERROR keystone.common.wsgi   File "/usr/lib/python2.7/dist-packages/keystone/resource/backends/sql.py", line 55, in get_project_by_name
2019-07-14 03:00:54.623 9182 ERROR keystone.common.wsgi     with sql.session_for_read() as session:
2019-07-14 03:00:54.623 9182 ERROR keystone.common.wsgi   File "/usr/lib/python2.7/contextlib.py", line 17, in __enter__
2019-07-14 03:00:54.623 9182 ERROR keystone.common.wsgi     return self.gen.next()
2019-07-14 03:00:54.623 9182 ERROR keystone.common.wsgi   File "/usr/lib/python2.7/dist-packages/oslo_db/sqlalchemy/enginefacade.py", line 1042, in _transaction_scope
2019-07-14 03:00:54.623 9182 ERROR keystone.common.wsgi     context=context) as resource:
2019-07-14 03:00:54.623 9182 ERROR keystone.common.wsgi   File "/usr/lib/python2.7/contextlib.py", line 17, in __enter__
2019-07-14 03:00:54.623 9182 ERROR keystone.common.wsgi     return self.gen.next()
2019-07-14 03:00:54.623 9182 ERROR keystone.common.wsgi   File "/usr/lib/python2.7/dist-packages/oslo_db/sqlalchemy/enginefacade.py", line 645, in _session
2019-07-14 03:00:54.623 9182 ERROR keystone.common.wsgi     bind=self.connection, mode=self.mode)
2019-07-14 03:00:54.623 9182 ERROR keystone.common.wsgi   File "/usr/lib/python2.7/dist-packages/oslo_db/sqlalchemy/enginefacade.py", line 409, in _create_session
2019-07-14 03:00:54.623 9182 ERROR keystone.common.wsgi     self._start()
2019-07-14 03:00:54.623 9182 ERROR keystone.common.wsgi   File "/usr/lib/python2.7/dist-packages/oslo_db/sqlalchemy/enginefacade.py", line 496, in _start
2019-07-14 03:00:54.623 9182 ERROR keystone.common.wsgi     engine_args, maker_args)
2019-07-14 03:00:54.623 9182 ERROR keystone.common.wsgi   File "/usr/lib/python2.7/dist-packages/oslo_db/sqlalchemy/enginefacade.py", line 520, in _setup_for_connection
2019-07-14 03:00:54.623 9182 ERROR keystone.common.wsgi     sql_connection=sql_connection, **engine_kwargs)
2019-07-14 03:00:54.623 9182 ERROR keystone.common.wsgi   File "/usr/lib/python2.7/dist-packages/debtcollector/renames.py", line 43, in decorator
2019-07-14 03:00:54.623 9182 ERROR keystone.common.wsgi     return wrapped(*args, **kwargs)
2019-07-14 03:00:54.623 9182 ERROR keystone.common.wsgi   File "/usr/lib/python2.7/dist-packages/oslo_db/sqlalchemy/engines.py", line 202, in create_engine
2019-07-14 03:00:54.623 9182 ERROR keystone.common.wsgi     test_conn = _test_connection(engine, max_retries, retry_interval)
2019-07-14 03:00:54.623 9182 ERROR keystone.common.wsgi   File "/usr/lib/python2.7/dist-packages/oslo_db/sqlalchemy/engines.py", line 388, in _test_connection
2019-07-14 03:00:54.623 9182 ERROR keystone.common.wsgi     six.reraise(type(de_ref), de_ref)
2019-07-14 03:00:54.623 9182 ERROR keystone.common.wsgi   File "<string>", line 3, in reraise
2019-07-14 03:00:54.623 9182 ERROR keystone.common.wsgi DBConnectionError: (pymysql.err.OperationalError) (2003, "Can't connect to MySQL server on 'controller' ([Errno 111] Connection refused)") (Background on this error at: http://sqlalche.me/e/e3q8)
2019-07-14 03:00:54.623 9182 ERROR keystone.common.wsgi 
2019-07-14 03:19:37.047 9179 INFO keyring.backend [-] Loading Windows (alt)
2019-07-14 03:19:37.060 9179 INFO keyring.backend [-] Loading pyfs
2019-07-14 03:19:37.061 9179 INFO keyring.backend [-] Loading multi
2019-07-14 03:19:37.062 9179 INFO keyring.backend [-] Loading Google
2019-07-14 03:19:37.064 9179 INFO keyring.backend [-] Loading Gnome
2019-07-14 03:19:37.070 9179 INFO keyring.backend [-] Loading keyczar
2019-07-14 03:19:37.071 9179 INFO keyring.backend [-] Loading file
2019-07-14 03:19:37.184 9179 INFO keystone.common.wsgi [req-0f24cff4-ebde-43f1-9426-20f45731bb3c - - - - -] POST http://controller:5000/v3/auth/tokens
2019-07-14 03:19:37.200 9179 WARNING oslo_db.sqlalchemy.engines [req-0f24cff4-ebde-43f1-9426-20f45731bb3c - - - - -] SQL connection failed. 10 attempts left.: DBConnectionError: (pymysql.err.OperationalError) (2003, "Can't connect to MySQL server on 'controller' ([Errno 111] Connection refused)") (Background on this error at: http://sqlalche.me/e/e3q8)
2019-07-14 03:19:47.212 9179 WARNING oslo_db.sqlalchemy.engines [req-0f24cff4-ebde-43f1-9426-20f45731bb3c - - - - -] SQL connection failed. 9 attempts left.: DBConnectionError: (pymysql.err.OperationalError) (2003, "Can't connect to MySQL server on 'controller' ([Errno 111] Connection refused)") (Background on this error at: http://sqlalche.me/e/e3q8)
2019-07-14 03:19:57.224 9179 WARNING oslo_db.sqlalchemy.engines [req-0f24cff4-ebde-43f1-9426-20f45731bb3c - - - - -] SQL connection failed. 8 attempts left.: DBConnectionError: (pymysql.err.OperationalError) (2003, "Can't connect to MySQL server on 'controller' ([Errno 111] Connection refused)") (Background on this error at: http://sqlalche.me/e/e3q8)
2019-07-14 03:24:22.720 1801 INFO keyring.backend [-] Loading Windows (alt)
2019-07-14 03:24:22.797 1801 INFO keyring.backend [-] Loading pyfs
2019-07-14 03:24:22.799 1801 INFO keyring.backend [-] Loading multi
2019-07-14 03:24:22.809 1801 INFO keyring.backend [-] Loading Google
2019-07-14 03:24:22.812 1801 INFO keyring.backend [-] Loading Gnome
2019-07-14 03:24:22.862 1801 INFO keyring.backend [-] Loading keyczar
2019-07-14 03:24:22.862 1801 INFO keyring.backend [-] Loading file
2019-07-14 03:24:24.889 1802 INFO keyring.backend [-] Loading Windows (alt)
2019-07-14 03:24:24.902 1802 INFO keyring.backend [-] Loading pyfs
2019-07-14 03:24:24.903 1802 INFO keyring.backend [-] Loading multi
2019-07-14 03:24:24.904 1802 INFO keyring.backend [-] Loading Google
2019-07-14 03:24:24.906 1802 INFO keyring.backend [-] Loading Gnome
2019-07-14 03:24:24.911 1802 INFO keyring.backend [-] Loading keyczar
2019-07-14 03:24:24.912 1802 INFO keyring.backend [-] Loading file
2019-07-14 03:24:25.019 1802 INFO keystone.common.wsgi [req-1fe8a07d-c152-479f-8122-40dbe515e400 - - - - -] POST http://controller:5000/v3/auth/tokens
2019-07-14 03:24:25.135 1802 WARNING oslo_db.sqlalchemy.engines [req-1fe8a07d-c152-479f-8122-40dbe515e400 - - - - -] SQL connection failed. 10 attempts left.: DBConnectionError: (pymysql.err.OperationalError) (2003, "Can't connect to MySQL server on 'controller' ([Errno 111] Connection refused)") (Background on this error at: http://sqlalche.me/e/e3q8)
2019-07-14 03:24:35.147 1802 WARNING oslo_db.sqlalchemy.engines [req-1fe8a07d-c152-479f-8122-40dbe515e400 - - - - -] SQL connection failed. 9 attempts left.: DBConnectionError: (pymysql.err.OperationalError) (2003, "Can't connect to MySQL server on 'controller' ([Errno 111] Connection refused)") (Background on this error at: http://sqlalche.me/e/e3q8)
2019-07-14 03:24:45.159 1802 WARNING oslo_db.sqlalchemy.engines [req-1fe8a07d-c152-479f-8122-40dbe515e400 - - - - -] SQL connection failed. 8 attempts left.: DBConnectionError: (pymysql.err.OperationalError) (2003, "Can't connect to MySQL server on 'controller' ([Errno 111] Connection refused)") (Background on this error at: http://sqlalche.me/e/e3q8)
2019-07-14 03:24:55.171 1802 WARNING oslo_db.sqlalchemy.engines [req-1fe8a07d-c152-479f-8122-40dbe515e400 - - - - -] SQL connection failed. 7 attempts left.: DBConnectionError: (pymysql.err.OperationalError) (2003, "Can't connect to MySQL server on 'controller' ([Errno 111] Connection refused)") (Background on this error at: http://sqlalche.me/e/e3q8)
2019-07-14 03:25:05.182 1802 WARNING oslo_db.sqlalchemy.engines [req-1fe8a07d-c152-479f-8122-40dbe515e400 - - - - -] SQL connection failed. 6 attempts left.: DBConnectionError: (pymysql.err.OperationalError) (2003, "Can't connect to MySQL server on 'controller' ([Errno 111] Connection refused)") (Background on this error at: http://sqlalche.me/e/e3q8)
2019-07-14 03:25:15.194 1802 WARNING oslo_db.sqlalchemy.engines [req-1fe8a07d-c152-479f-8122-40dbe515e400 - - - - -] SQL connection failed. 5 attempts left.: DBConnectionError: (pymysql.err.OperationalError) (2003, "Can't connect to MySQL server on 'controller' ([Errno 111] Connection refused)") (Background on this error at: http://sqlalche.me/e/e3q8)
2019-07-14 03:25:25.205 1802 WARNING oslo_db.sqlalchemy.engines [req-1fe8a07d-c152-479f-8122-40dbe515e400 - - - - -] SQL connection failed. 4 attempts left.: DBConnectionError: (pymysql.err.OperationalError) (2003, "Can't connect to MySQL server on 'controller' ([Errno 111] Connection refused)") (Background on this error at: http://sqlalche.me/e/e3q8)
2019-07-14 03:25:35.217 1802 WARNING oslo_db.sqlalchemy.engines [req-1fe8a07d-c152-479f-8122-40dbe515e400 - - - - -] SQL connection failed. 3 attempts left.: DBConnectionError: (pymysql.err.OperationalError) (2003, "Can't connect to MySQL server on 'controller' ([Errno 111] Connection refused)") (Background on this error at: http://sqlalche.me/e/e3q8)
2019-07-14 03:25:45.229 1802 WARNING oslo_db.sqlalchemy.engines [req-1fe8a07d-c152-479f-8122-40dbe515e400 - - - - -] SQL connection failed. 2 attempts left.: DBConnectionError: (pymysql.err.OperationalError) (2003, "Can't connect to MySQL server on 'controller' ([Errno 111] Connection refused)") (Background on this error at: http://sqlalche.me/e/e3q8)
2019-07-14 03:25:55.240 1802 WARNING oslo_db.sqlalchemy.engines [req-1fe8a07d-c152-479f-8122-40dbe515e400 - - - - -] SQL connection failed. 1 attempts left.: DBConnectionError: (pymysql.err.OperationalError) (2003, "Can't connect to MySQL server on 'controller' ([Errno 111] Connection refused)") (Background on this error at: http://sqlalche.me/e/e3q8)
2019-07-14 03:26:05.251 1802 ERROR keystone.common.wsgi [req-1fe8a07d-c152-479f-8122-40dbe515e400 - - - - -] (pymysql.err.OperationalError) (2003, "Can't connect to MySQL server on 'controller' ([Errno 111] Connection refused)") (Background on this error at: http://sqlalche.me/e/e3q8): DBConnectionError: (pymysql.err.OperationalError) (2003, "Can't connect to MySQL server on 'controller' ([Errno 111] Connection refused)") (Background on this error at: http://sqlalche.me/e/e3q8)
2019-07-14 03:26:05.251 1802 ERROR keystone.common.wsgi Traceback (most recent call last):
2019-07-14 03:26:05.251 1802 ERROR keystone.common.wsgi   File "/usr/lib/python2.7/dist-packages/keystone/common/wsgi.py", line 148, in __call__
2019-07-14 03:26:05.251 1802 ERROR keystone.common.wsgi     result = method(req, **params)
2019-07-14 03:26:05.251 1802 ERROR keystone.common.wsgi   File "/usr/lib/python2.7/dist-packages/keystone/auth/controllers.py", line 64, in authenticate_for_token
2019-07-14 03:26:05.251 1802 ERROR keystone.common.wsgi     auth_info = core.AuthInfo.create(auth=auth)
2019-07-14 03:26:05.251 1802 ERROR keystone.common.wsgi   File "/usr/lib/python2.7/dist-packages/keystone/auth/core.py", line 128, in create
2019-07-14 03:26:05.251 1802 ERROR keystone.common.wsgi     auth_info._validate_and_normalize_auth_data(scope_only)
2019-07-14 03:26:05.251 1802 ERROR keystone.common.wsgi   File "/usr/lib/python2.7/dist-packages/keystone/auth/core.py", line 336, in _validate_and_normalize_auth_data
2019-07-14 03:26:05.251 1802 ERROR keystone.common.wsgi     self._validate_and_normalize_scope_data()
2019-07-14 03:26:05.251 1802 ERROR keystone.common.wsgi   File "/usr/lib/python2.7/dist-packages/keystone/auth/core.py", line 286, in _validate_and_normalize_scope_data
2019-07-14 03:26:05.251 1802 ERROR keystone.common.wsgi     project_ref = self._lookup_project(self.auth['scope']['project'])
2019-07-14 03:26:05.251 1802 ERROR keystone.common.wsgi   File "/usr/lib/python2.7/dist-packages/keystone/auth/core.py", line 196, in _lookup_project
2019-07-14 03:26:05.251 1802 ERROR keystone.common.wsgi     domain_ref = self._lookup_domain(project_info['domain'])
2019-07-14 03:26:05.251 1802 ERROR keystone.common.wsgi   File "/usr/lib/python2.7/dist-packages/keystone/auth/core.py", line 174, in _lookup_domain
2019-07-14 03:26:05.251 1802 ERROR keystone.common.wsgi     domain_name)
2019-07-14 03:26:05.251 1802 ERROR keystone.common.wsgi   File "/usr/lib/python2.7/dist-packages/keystone/common/manager.py", line 116, in wrapped
2019-07-14 03:26:05.251 1802 ERROR keystone.common.wsgi     __ret_val = __f(*args, **kwargs)
2019-07-14 03:26:05.251 1802 ERROR keystone.common.wsgi   File "/usr/lib/python2.7/dist-packages/dogpile/cache/region.py", line 1220, in decorate
2019-07-14 03:26:05.251 1802 ERROR keystone.common.wsgi     should_cache_fn)
2019-07-14 03:26:05.251 1802 ERROR keystone.common.wsgi   File "/usr/lib/python2.7/dist-packages/dogpile/cache/region.py", line 825, in get_or_create
2019-07-14 03:26:05.251 1802 ERROR keystone.common.wsgi     async_creator) as value:
2019-07-14 03:26:05.251 1802 ERROR keystone.common.wsgi   File "/usr/lib/python2.7/dist-packages/dogpile/lock.py", line 154, in __enter__
2019-07-14 03:26:05.251 1802 ERROR keystone.common.wsgi     return self._enter()
2019-07-14 03:26:05.251 1802 ERROR keystone.common.wsgi   File "/usr/lib/python2.7/dist-packages/dogpile/lock.py", line 94, in _enter
2019-07-14 03:26:05.251 1802 ERROR keystone.common.wsgi     generated = self._enter_create(createdtime)
2019-07-14 03:26:05.251 1802 ERROR keystone.common.wsgi   File "/usr/lib/python2.7/dist-packages/dogpile/lock.py", line 145, in _enter_create
2019-07-14 03:26:05.251 1802 ERROR keystone.common.wsgi     created = self.creator()
2019-07-14 03:26:05.251 1802 ERROR keystone.common.wsgi   File "/usr/lib/python2.7/dist-packages/dogpile/cache/region.py", line 792, in gen_value
2019-07-14 03:26:05.251 1802 ERROR keystone.common.wsgi     created_value = creator()
2019-07-14 03:26:05.251 1802 ERROR keystone.common.wsgi   File "/usr/lib/python2.7/dist-packages/dogpile/cache/region.py", line 1216, in creator
2019-07-14 03:26:05.251 1802 ERROR keystone.common.wsgi     return fn(*arg, **kw)
2019-07-14 03:26:05.251 1802 ERROR keystone.common.wsgi   File "/usr/lib/python2.7/dist-packages/keystone/resource/core.py", line 716, in get_domain_by_name
2019-07-14 03:26:05.251 1802 ERROR keystone.common.wsgi     domain_id=None)
2019-07-14 03:26:05.251 1802 ERROR keystone.common.wsgi   File "/usr/lib/python2.7/dist-packages/keystone/resource/backends/sql.py", line 55, in get_project_by_name
2019-07-14 03:26:05.251 1802 ERROR keystone.common.wsgi     with sql.session_for_read() as session:
2019-07-14 03:26:05.251 1802 ERROR keystone.common.wsgi   File "/usr/lib/python2.7/contextlib.py", line 17, in __enter__
2019-07-14 03:26:05.251 1802 ERROR keystone.common.wsgi     return self.gen.next()
2019-07-14 03:26:05.251 1802 ERROR keystone.common.wsgi   File "/usr/lib/python2.7/dist-packages/oslo_db/sqlalchemy/enginefacade.py", line 1042, in _transaction_scope
2019-07-14 03:26:05.251 1802 ERROR keystone.common.wsgi     context=context) as resource:
2019-07-14 03:26:05.251 1802 ERROR keystone.common.wsgi   File "/usr/lib/python2.7/contextlib.py", line 17, in __enter__
2019-07-14 03:26:05.251 1802 ERROR keystone.common.wsgi     return self.gen.next()
2019-07-14 03:26:05.251 1802 ERROR keystone.common.wsgi   File "/usr/lib/python2.7/dist-packages/oslo_db/sqlalchemy/enginefacade.py", line 645, in _session
2019-07-14 03:26:05.251 1802 ERROR keystone.common.wsgi     bind=self.connection, mode=self.mode)
2019-07-14 03:26:05.251 1802 ERROR keystone.common.wsgi   File "/usr/lib/python2.7/dist-packages/oslo_db/sqlalchemy/enginefacade.py", line 409, in _create_session
2019-07-14 03:26:05.251 1802 ERROR keystone.common.wsgi     self._start()
2019-07-14 03:26:05.251 1802 ERROR keystone.common.wsgi   File "/usr/lib/python2.7/dist-packages/oslo_db/sqlalchemy/enginefacade.py", line 496, in _start
2019-07-14 03:26:05.251 1802 ERROR keystone.common.wsgi     engine_args, maker_args)
2019-07-14 03:26:05.251 1802 ERROR keystone.common.wsgi   File "/usr/lib/python2.7/dist-packages/oslo_db/sqlalchemy/enginefacade.py", line 520, in _setup_for_connection
2019-07-14 03:26:05.251 1802 ERROR keystone.common.wsgi     sql_connection=sql_connection, **engine_kwargs)
2019-07-14 03:26:05.251 1802 ERROR keystone.common.wsgi   File "/usr/lib/python2.7/dist-packages/debtcollector/renames.py", line 43, in decorator
2019-07-14 03:26:05.251 1802 ERROR keystone.common.wsgi     return wrapped(*args, **kwargs)
2019-07-14 03:26:05.251 1802 ERROR keystone.common.wsgi   File "/usr/lib/python2.7/dist-packages/oslo_db/sqlalchemy/engines.py", line 202, in create_engine
2019-07-14 03:26:05.251 1802 ERROR keystone.common.wsgi     test_conn = _test_connection(engine, max_retries, retry_interval)
2019-07-14 03:26:05.251 1802 ERROR keystone.common.wsgi   File "/usr/lib/python2.7/dist-packages/oslo_db/sqlalchemy/engines.py", line 388, in _test_connection
2019-07-14 03:26:05.251 1802 ERROR keystone.common.wsgi     six.reraise(type(de_ref), de_ref)
2019-07-14 03:26:05.251 1802 ERROR keystone.common.wsgi   File "<string>", line 3, in reraise
2019-07-14 03:26:05.251 1802 ERROR keystone.common.wsgi DBConnectionError: (pymysql.err.OperationalError) (2003, "Can't connect to MySQL server on 'controller' ([Errno 111] Connection refused)") (Background on this error at: http://sqlalche.me/e/e3q8)
2019-07-14 03:26:05.251 1802 ERROR keystone.common.wsgi 
2019-07-14 03:41:19.500 1803 INFO keyring.backend [-] Loading Windows (alt)
2019-07-14 03:41:19.514 1803 INFO keyring.backend [-] Loading pyfs
2019-07-14 03:41:19.515 1803 INFO keyring.backend [-] Loading multi
2019-07-14 03:41:19.515 1803 INFO keyring.backend [-] Loading Google
2019-07-14 03:41:19.517 1803 INFO keyring.backend [-] Loading Gnome
2019-07-14 03:41:19.523 1803 INFO keyring.backend [-] Loading keyczar
2019-07-14 03:41:19.523 1803 INFO keyring.backend [-] Loading file
2019-07-14 03:41:19.561 1802 INFO keystone.common.wsgi [req-34354a73-8775-4b9b-b469-0aa2577e426d - - - - -] POST http://controller:5000/v3/auth/tokens
2019-07-14 03:41:19.645 1802 WARNING keystone.auth.core [req-34354a73-8775-4b9b-b469-0aa2577e426d - - - - -] Could not find domain: Default.: DomainNotFound: Could not find domain: Default.
2019-07-14 03:41:19.645 1802 WARNING keystone.common.wsgi [req-34354a73-8775-4b9b-b469-0aa2577e426d - - - - -] Authorization failed. The request you have made requires authentication. from 185.4.30.234: Unauthorized: The request you have made requires authentication.
2019-07-14 12:28:44.587 1800 INFO keyring.backend [-] Loading Windows (alt)
2019-07-14 12:28:44.602 1800 INFO keyring.backend [-] Loading pyfs
2019-07-14 12:28:44.603 1800 INFO keyring.backend [-] Loading multi
2019-07-14 12:28:44.603 1800 INFO keyring.backend [-] Loading Google
2019-07-14 12:28:44.606 1800 INFO keyring.backend [-] Loading Gnome
2019-07-14 12:28:44.611 1800 INFO keyring.backend [-] Loading keyczar
2019-07-14 12:28:44.611 1800 INFO keyring.backend [-] Loading file
2019-07-14 12:28:46.521 1799 INFO keyring.backend [-] Loading Windows (alt)
2019-07-14 12:28:46.534 1799 INFO keyring.backend [-] Loading pyfs
2019-07-14 12:28:46.535 1799 INFO keyring.backend [-] Loading multi
2019-07-14 12:28:46.536 1799 INFO keyring.backend [-] Loading Google
2019-07-14 12:28:46.538 1799 INFO keyring.backend [-] Loading Gnome
2019-07-14 12:28:46.543 1799 INFO keyring.backend [-] Loading keyczar
2019-07-14 12:28:46.544 1799 INFO keyring.backend [-] Loading file
2019-07-14 12:28:46.651 1799 INFO keystone.common.wsgi [req-f007b561-0214-4081-b54d-b1c30b77d3ed - - - - -] POST http://controller:5000/v3/auth/tokens
2019-07-14 12:28:46.747 1799 WARNING keystone.auth.core [req-f007b561-0214-4081-b54d-b1c30b77d3ed - - - - -] Could not find domain: Default.: DomainNotFound: Could not find domain: Default.
2019-07-14 12:28:46.748 1799 WARNING keystone.common.wsgi [req-f007b561-0214-4081-b54d-b1c30b77d3ed - - - - -] Authorization failed. The request you have made requires authentication. from 185.4.30.234: Unauthorized: The request you have made requires authentication.
2019-07-14 12:29:22.390 1802 INFO keystone.common.wsgi [req-2501477e-086e-451f-a71c-9ee624f8217b - - - - -] POST http://controller:5000/v3/auth/tokens
2019-07-14 12:29:24.103 1800 INFO keystone.common.wsgi [req-c9c56a2e-fea9-44ac-b251-ea5e10d3ab86 - - - - -] POST http://controller:5000/v3/auth/tokens
2019-07-14 12:29:25.447 1803 INFO keystone.common.wsgi [req-b87347f6-0494-4bbf-a084-25ff132566ec 785f07946de94262a9f3f0919caec198 eb000ab3fcb94b48ad447d1785a53d5c - default default] POST http://controller:5000/v3/domains
2019-07-14 12:29:25.476 1803 WARNING py.warnings [req-b87347f6-0494-4bbf-a084-25ff132566ec 785f07946de94262a9f3f0919caec198 eb000ab3fcb94b48ad447d1785a53d5c - default default] /usr/lib/python2.7/dist-packages/oslo_policy/policy.py:896: UserWarning: Policy identity:create_domain failed scope check. The token used to make the request was project scoped but the policy requires ['system'] scope. This behavior may change in the future where using the intended scope is required
  warnings.warn(msg)

2019-07-14 12:32:39.000 1801 INFO keystone.common.wsgi [req-395b759d-15d3-4648-8153-939c914bc194 - - - - -] POST http://controller:5000/v3/auth/tokens
2019-07-14 12:32:39.893 1800 INFO keystone.common.wsgi [req-99311f7b-54eb-45b1-b7a3-6a9f107e68d6 - - - - -] POST http://controller:5000/v3/auth/tokens
2019-07-14 12:32:40.640 1801 INFO keystone.common.wsgi [req-e6c29c55-c1f8-4923-b82d-d1bda13f9edb 785f07946de94262a9f3f0919caec198 eb000ab3fcb94b48ad447d1785a53d5c - default default] GET http://controller:5000/v3/domains/default
2019-07-14 12:32:40.661 1801 WARNING py.warnings [req-e6c29c55-c1f8-4923-b82d-d1bda13f9edb 785f07946de94262a9f3f0919caec198 eb000ab3fcb94b48ad447d1785a53d5c - default default] /usr/lib/python2.7/dist-packages/oslo_policy/policy.py:896: UserWarning: Policy identity:get_domain failed scope check. The token used to make the request was project scoped but the policy requires ['system'] scope. This behavior may change in the future where using the intended scope is required
  warnings.warn(msg)

2019-07-14 12:32:41.007 1799 INFO keystone.common.wsgi [req-e9187694-62d2-4430-acc5-159acc17cc69 785f07946de94262a9f3f0919caec198 eb000ab3fcb94b48ad447d1785a53d5c - default default] POST http://controller:5000/v3/projects
2019-07-14 12:32:41.027 1799 WARNING py.warnings [req-e9187694-62d2-4430-acc5-159acc17cc69 785f07946de94262a9f3f0919caec198 eb000ab3fcb94b48ad447d1785a53d5c - default default] /usr/lib/python2.7/dist-packages/oslo_policy/policy.py:896: UserWarning: Policy identity:create_project failed scope check. The token used to make the request was project scoped but the policy requires ['system'] scope. This behavior may change in the future where using the intended scope is required
  warnings.warn(msg)

2019-07-14 12:33:57.312 1799 INFO keystone.common.wsgi [req-3879e9c3-a60f-4d63-9342-257d69d61393 - - - - -] POST http://controller:5000/v3/auth/tokens
2019-07-14 12:33:57.989 1802 INFO keystone.common.wsgi [req-6abfe0df-5901-484b-b356-3308bf58406e - - - - -] POST http://controller:5000/v3/auth/tokens
2019-07-14 12:33:58.735 1799 INFO keystone.common.wsgi [req-3c635438-8df3-435c-8d3b-7ee3cd3e6dbb 785f07946de94262a9f3f0919caec198 eb000ab3fcb94b48ad447d1785a53d5c - default default] GET http://controller:5000/v3/domains/default
2019-07-14 12:33:58.754 1799 WARNING py.warnings [req-3c635438-8df3-435c-8d3b-7ee3cd3e6dbb 785f07946de94262a9f3f0919caec198 eb000ab3fcb94b48ad447d1785a53d5c - default default] /usr/lib/python2.7/dist-packages/oslo_policy/policy.py:896: UserWarning: Policy identity:get_domain failed scope check. The token used to make the request was project scoped but the policy requires ['system'] scope. This behavior may change in the future where using the intended scope is required
  warnings.warn(msg)

2019-07-14 12:33:58.895 1802 INFO keystone.common.wsgi [req-04fb0248-30db-43df-9e58-af9a98a83862 785f07946de94262a9f3f0919caec198 eb000ab3fcb94b48ad447d1785a53d5c - default default] POST http://controller:5000/v3/projects
2019-07-14 12:33:58.916 1802 WARNING py.warnings [req-04fb0248-30db-43df-9e58-af9a98a83862 785f07946de94262a9f3f0919caec198 eb000ab3fcb94b48ad447d1785a53d5c - default default] /usr/lib/python2.7/dist-packages/oslo_policy/policy.py:896: UserWarning: Policy identity:create_project failed scope check. The token used to make the request was project scoped but the policy requires ['system'] scope. This behavior may change in the future where using the intended scope is required
  warnings.warn(msg)

2019-07-14 12:34:16.726 1803 INFO keystone.common.wsgi [req-0d02022b-cc3d-4b09-a24e-0128751739a2 - - - - -] POST http://controller:5000/v3/auth/tokens
2019-07-14 12:34:17.409 1799 INFO keystone.common.wsgi [req-1bc7f63c-a4d4-4389-aea8-1b06ba784c9b - - - - -] POST http://controller:5000/v3/auth/tokens
2019-07-14 12:34:18.146 1803 INFO keystone.common.wsgi [req-c80ce423-64f9-4fa1-87bd-010edc6b9f8b 785f07946de94262a9f3f0919caec198 eb000ab3fcb94b48ad447d1785a53d5c - default default] GET http://controller:5000/v3/domains/default
2019-07-14 12:34:18.164 1803 WARNING py.warnings [req-c80ce423-64f9-4fa1-87bd-010edc6b9f8b 785f07946de94262a9f3f0919caec198 eb000ab3fcb94b48ad447d1785a53d5c - default default] /usr/lib/python2.7/dist-packages/oslo_policy/policy.py:896: UserWarning: Policy identity:get_domain failed scope check. The token used to make the request was project scoped but the policy requires ['system'] scope. This behavior may change in the future where using the intended scope is required
  warnings.warn(msg)

2019-07-14 12:34:25.746 1800 INFO keystone.common.wsgi [req-f2b68781-bbe2-48cf-8369-df5aa4641476 785f07946de94262a9f3f0919caec198 eb000ab3fcb94b48ad447d1785a53d5c - default default] POST http://controller:5000/v3/users
2019-07-14 12:34:25.768 1800 WARNING py.warnings [req-f2b68781-bbe2-48cf-8369-df5aa4641476 785f07946de94262a9f3f0919caec198 eb000ab3fcb94b48ad447d1785a53d5c - default default] /usr/lib/python2.7/dist-packages/oslo_policy/policy.py:896: UserWarning: Policy identity:create_user failed scope check. The token used to make the request was project scoped but the policy requires ['system'] scope. This behavior may change in the future where using the intended scope is required
  warnings.warn(msg)

2019-07-14 12:34:37.659 1799 INFO keystone.common.wsgi [req-9aa49ec6-f3d8-487a-a7e0-7be2ecc8aff7 - - - - -] POST http://controller:5000/v3/auth/tokens
2019-07-14 12:34:38.299 1803 INFO keystone.common.wsgi [req-6dcd27df-e198-4f58-8331-3686e4bb833f - - - - -] POST http://controller:5000/v3/auth/tokens
2019-07-14 12:34:39.031 1799 INFO keystone.common.wsgi [req-62bc6130-eb2e-4d33-aff0-239db2c730e2 785f07946de94262a9f3f0919caec198 eb000ab3fcb94b48ad447d1785a53d5c - default default] POST http://controller:5000/v3/roles
2019-07-14 12:34:39.046 1799 WARNING py.warnings [req-62bc6130-eb2e-4d33-aff0-239db2c730e2 785f07946de94262a9f3f0919caec198 eb000ab3fcb94b48ad447d1785a53d5c - default default] /usr/lib/python2.7/dist-packages/oslo_policy/policy.py:896: UserWarning: Policy identity:create_role failed scope check. The token used to make the request was project scoped but the policy requires ['system'] scope. This behavior may change in the future where using the intended scope is required
  warnings.warn(msg)

2019-07-14 12:34:46.564 1801 INFO keystone.common.wsgi [req-0ef6d605-0848-4f23-a6e1-0ef5402154c7 - - - - -] POST http://controller:5000/v3/auth/tokens
2019-07-14 12:34:47.186 1799 INFO keystone.common.wsgi [req-d9dd1c69-4f05-4c66-ba43-58882f8018cb - - - - -] POST http://controller:5000/v3/auth/tokens
2019-07-14 12:34:47.946 1803 INFO keystone.common.wsgi [req-094ec132-5e8c-4ec0-9e70-a774f3594fd1 785f07946de94262a9f3f0919caec198 eb000ab3fcb94b48ad447d1785a53d5c - default default] GET http://controller:5000/v3/roles/myrole
2019-07-14 12:34:47.959 1803 WARNING keystone.common.wsgi [req-094ec132-5e8c-4ec0-9e70-a774f3594fd1 785f07946de94262a9f3f0919caec198 eb000ab3fcb94b48ad447d1785a53d5c - default default] Could not find role: myrole.: RoleNotFound: Could not find role: myrole.
2019-07-14 12:34:48.089 1799 INFO keystone.common.wsgi [req-0b6e789c-46fb-4681-a825-3c2f4a0ec472 785f07946de94262a9f3f0919caec198 eb000ab3fcb94b48ad447d1785a53d5c - default default] GET http://controller:5000/v3/roles?name=myrole
2019-07-14 12:34:48.106 1799 WARNING py.warnings [req-0b6e789c-46fb-4681-a825-3c2f4a0ec472 785f07946de94262a9f3f0919caec198 eb000ab3fcb94b48ad447d1785a53d5c - default default] /usr/lib/python2.7/dist-packages/oslo_policy/policy.py:896: UserWarning: Policy identity:list_roles failed scope check. The token used to make the request was project scoped but the policy requires ['system'] scope. This behavior may change in the future where using the intended scope is required
  warnings.warn(msg)

2019-07-14 12:34:48.268 1803 INFO keystone.common.wsgi [req-413587eb-99ab-4b41-82e8-054ae08ee0b5 785f07946de94262a9f3f0919caec198 eb000ab3fcb94b48ad447d1785a53d5c - default default] GET http://controller:5000/v3/users/myuser
2019-07-14 12:34:48.279 1803 WARNING keystone.common.wsgi [req-413587eb-99ab-4b41-82e8-054ae08ee0b5 785f07946de94262a9f3f0919caec198 eb000ab3fcb94b48ad447d1785a53d5c - default default] Could not find user: myuser.: UserNotFound: Could not find user: myuser.
2019-07-14 12:34:48.430 1800 INFO keystone.common.wsgi [req-9ef57b7c-0a65-4639-babd-e7c2c9d310b2 785f07946de94262a9f3f0919caec198 eb000ab3fcb94b48ad447d1785a53d5c - default default] GET http://controller:5000/v3/users?name=myuser
2019-07-14 12:34:48.451 1800 WARNING py.warnings [req-9ef57b7c-0a65-4639-babd-e7c2c9d310b2 785f07946de94262a9f3f0919caec198 eb000ab3fcb94b48ad447d1785a53d5c - default default] /usr/lib/python2.7/dist-packages/oslo_policy/policy.py:896: UserWarning: Policy identity:list_users failed scope check. The token used to make the request was project scoped but the policy requires ['system'] scope. This behavior may change in the future where using the intended scope is required
  warnings.warn(msg)

2019-07-14 12:35:16.751 1801 INFO keystone.common.wsgi [req-abbd794a-7bdd-477b-9ed6-b3265e265765 - - - - -] POST http://controller:5000/v3/auth/tokens
2019-07-14 12:35:17.382 1802 INFO keystone.common.wsgi [req-e1e25d38-ce66-41e4-ac6b-b5e31ae296ba - - - - -] POST http://controller:5000/v3/auth/tokens
2019-07-14 12:35:18.140 1801 INFO keystone.common.wsgi [req-374738b5-c011-4868-b2c6-dc8dc14b2c94 785f07946de94262a9f3f0919caec198 eb000ab3fcb94b48ad447d1785a53d5c - default default] GET http://controller:5000/v3/roles/myrole
2019-07-14 12:35:18.148 1801 WARNING keystone.common.wsgi [req-374738b5-c011-4868-b2c6-dc8dc14b2c94 785f07946de94262a9f3f0919caec198 eb000ab3fcb94b48ad447d1785a53d5c - default default] Could not find role: myrole.: RoleNotFound: Could not find role: myrole.
2019-07-14 12:35:18.285 1799 INFO keystone.common.wsgi [req-eeb4a67b-d562-4660-bb1c-d15582005fc5 785f07946de94262a9f3f0919caec198 eb000ab3fcb94b48ad447d1785a53d5c - default default] GET http://controller:5000/v3/roles?name=myrole
2019-07-14 12:35:18.443 1800 INFO keystone.common.wsgi [req-e8648b5e-c15a-45a3-8fac-0ff073b49528 785f07946de94262a9f3f0919caec198 eb000ab3fcb94b48ad447d1785a53d5c - default default] GET http://controller:5000/v3/users/antisec
2019-07-14 12:35:18.454 1800 WARNING keystone.common.wsgi [req-e8648b5e-c15a-45a3-8fac-0ff073b49528 785f07946de94262a9f3f0919caec198 eb000ab3fcb94b48ad447d1785a53d5c - default default] Could not find user: antisec.: UserNotFound: Could not find user: antisec.
2019-07-14 12:35:18.588 1799 INFO keystone.common.wsgi [req-093d8273-9ea7-4521-86f8-71728a6c04b6 785f07946de94262a9f3f0919caec198 eb000ab3fcb94b48ad447d1785a53d5c - default default] GET http://controller:5000/v3/users?name=antisec
2019-07-14 12:35:18.603 1799 WARNING py.warnings [req-093d8273-9ea7-4521-86f8-71728a6c04b6 785f07946de94262a9f3f0919caec198 eb000ab3fcb94b48ad447d1785a53d5c - default default] /usr/lib/python2.7/dist-packages/oslo_policy/policy.py:896: UserWarning: Policy identity:list_users failed scope check. The token used to make the request was project scoped but the policy requires ['system'] scope. This behavior may change in the future where using the intended scope is required
  warnings.warn(msg)

2019-07-14 12:35:18.897 1803 INFO keystone.common.wsgi [req-7da77489-dee2-4aba-b98b-df0e3c6d40dd 785f07946de94262a9f3f0919caec198 eb000ab3fcb94b48ad447d1785a53d5c - default default] GET http://controller:5000/v3/projects/GreenWebDemoProject
2019-07-14 12:35:18.902 1803 WARNING keystone.common.wsgi [req-7da77489-dee2-4aba-b98b-df0e3c6d40dd 785f07946de94262a9f3f0919caec198 eb000ab3fcb94b48ad447d1785a53d5c - default default] Could not find project: GreenWebDemoProject.: ProjectNotFound: Could not find project: GreenWebDemoProject.
2019-07-14 12:35:19.036 1799 INFO keystone.common.wsgi [req-32eb2f3c-4c76-46b6-b955-cb8cd91cceef 785f07946de94262a9f3f0919caec198 eb000ab3fcb94b48ad447d1785a53d5c - default default] GET http://controller:5000/v3/projects?name=GreenWebDemoProject
2019-07-14 12:35:19.050 1799 WARNING py.warnings [req-32eb2f3c-4c76-46b6-b955-cb8cd91cceef 785f07946de94262a9f3f0919caec198 eb000ab3fcb94b48ad447d1785a53d5c - default default] /usr/lib/python2.7/dist-packages/oslo_policy/policy.py:896: UserWarning: Policy identity:list_projects failed scope check. The token used to make the request was project scoped but the policy requires ['system'] scope. This behavior may change in the future where using the intended scope is required
  warnings.warn(msg)

2019-07-14 12:35:19.191 1802 INFO keystone.common.wsgi [req-ec7e06d9-4a8e-42b7-85b7-180f08304a6d 785f07946de94262a9f3f0919caec198 eb000ab3fcb94b48ad447d1785a53d5c - default default] PUT http://controller:5000/v3/projects/d8f946a866c1414c8f0fa30e378c5afd/users/0af5cc7c537442d8b8cc43ab7eae8ce2/roles/d6160bcb09094db2be3891297fc2e069
2019-07-14 12:35:19.250 1802 WARNING py.warnings [req-ec7e06d9-4a8e-42b7-85b7-180f08304a6d 785f07946de94262a9f3f0919caec198 eb000ab3fcb94b48ad447d1785a53d5c - default default] /usr/lib/python2.7/dist-packages/oslo_policy/policy.py:896: UserWarning: Policy identity:create_grant failed scope check. The token used to make the request was project scoped but the policy requires ['system'] scope. This behavior may change in the future where using the intended scope is required
  warnings.warn(msg)

2019-07-14 12:41:17.859 1801 INFO keystone.common.wsgi [req-5c9a5a96-1ca1-43fb-a485-ad47330f4108 - - - - -] POST http://controller:5000/v3/auth/tokens
2019-07-14 12:41:17.861 1801 WARNING keystone.common.wsgi [req-5c9a5a96-1ca1-43fb-a485-ad47330f4108 - - - - -] Expecting to find domain in project. The server could not comply with the request since it is either malformed or otherwise incorrect. The client is assumed to be in error.: ValidationError: Expecting to find domain in project. The server could not comply with the request since it is either malformed or otherwise incorrect. The client is assumed to be in error.
2019-07-14 12:41:46.834 1800 INFO keystone.common.wsgi [req-225aab62-ed61-40eb-aa77-a1cc1a9720f4 - - - - -] POST http://controller:5000/v3/auth/tokens
2019-07-14 12:41:46.836 1800 WARNING keystone.common.wsgi [req-225aab62-ed61-40eb-aa77-a1cc1a9720f4 - - - - -] Expecting to find domain in project. The server could not comply with the request since it is either malformed or otherwise incorrect. The client is assumed to be in error.: ValidationError: Expecting to find domain in project. The server could not comply with the request since it is either malformed or otherwise incorrect. The client is assumed to be in error.
2019-07-14 12:42:01.958 1800 INFO keystone.common.wsgi [req-b3db591f-470f-435d-ba5b-f8ffddabaadd - - - - -] POST http://controller:5000/v3/auth/tokens
2019-07-14 12:42:38.985 1800 INFO keystone.common.wsgi [req-8aae2d48-4442-4bf3-8d30-32e122660594 - - - - -] POST http://controller:5000/v3/auth/tokens
2019-07-14 12:42:39.546 1800 WARNING keystone.common.wsgi [req-8aae2d48-4442-4bf3-8d30-32e122660594 - - - - -] Authorization failed. The request you have made requires authentication. from 185.4.30.234: Unauthorized: The request you have made requires authentication.
2019-07-14 12:42:54.402 1800 INFO keystone.common.wsgi [req-68185941-e72a-423c-a650-bb57be988ab1 - - - - -] POST http://controller:5000/v3/auth/tokens
2019-07-14 12:42:54.954 1800 WARNING keystone.common.wsgi [req-68185941-e72a-423c-a650-bb57be988ab1 - - - - -] Authorization failed. The request you have made requires authentication. from 185.4.30.234: Unauthorized: The request you have made requires authentication.
2019-07-14 12:43:02.628 1800 INFO keystone.common.wsgi [req-9643dd5a-f951-4403-b552-e16a4ee3fdd8 - - - - -] POST http://controller:5000/v3/auth/tokens
2019-07-14 12:43:03.168 1800 WARNING keystone.common.wsgi [req-9643dd5a-f951-4403-b552-e16a4ee3fdd8 - - - - -] Authorization failed. The request you have made requires authentication. from 185.4.30.234: Unauthorized: The request you have made requires authentication.
2019-07-14 12:43:16.012 1802 INFO keystone.common.wsgi [req-68a646bd-6e67-4891-97f9-a2d2b1b04c80 - - - - -] POST http://controller:5000/v3/auth/tokens
2019-07-14 13:39:24.171 1803 INFO keystone.common.wsgi [req-d07a6a4d-889c-40a4-88c7-bb87834e85da - - - - -] POST http://controller:5000/v3/auth/tokens
